Workbook

Sheet Global
A1: Mes | B1: Opc/Futuros | C1: Acciones | D1: Bonos | E1: Cedear | F1: ON | G1: FCI | H1: Letras | I1: Cripto | J1: Efectivo | K1: Total | L1: Variacion | M1: Inflacion | O1: Variacion Total | P1: Inflacion Total | Q1: P&L Final
A2: Enero | B2: =IFERROR(INDIRECT($A2&"!$N1"),0) -> 0 | C2: =IFERROR(INDIRECT($A2&"!$N2"),0) -> 478288.5 | D2: =IFERROR(INDIRECT($A2&"!$N3"),0) -> 225608 | E2: =IFERROR(INDIRECT($A2&"!$N4"),0) -> 493990 | F2: =IFERROR(INDIRECT($A2&"!$N5"),0) -> 31148 | G2: =IFERROR(INDIRECT($A2&"!$N6"),0) -> 1338770.1 | H2: =IFERROR(INDIRECT($A2&"!$N7"),0) -> 28744.249 | I2: =IFERROR(INDIRECT($A2&"!$N8"),0) -> 22000 | J2: =IFERROR(INDIRECT($A2&"!$N9"),0) -> 50856.87 | K2: =SUM(B2:J2) -> 2669405.7 | L2: =Enero!D2 -> 0.01610312 | M2: 0.022 | O2: =SUM(L2:L13) -> 0.43860346 | P2: =SUM(M2:M13) -> 0.1572
A3: Febrero | B3: =IFERROR(INDIRECT($A3&"!$N1"),0) -> 0 | C3: =IFERROR(INDIRECT($A3&"!$N2"),0) -> 429801.5 | D3: =IFERROR(INDIRECT($A3&"!$N3"),0) -> 728440.79 | E3: =IFERROR(INDIRECT($A3&"!$N4"),0) -> 478840 | F3: =IFERROR(INDIRECT($A3&"!$N5"),0) -> 37599 | G3: =IFERROR(INDIRECT($A3&"!$N6"),0) -> 1307699.7 | H3: =IFERROR(INDIRECT($A3&"!$N7"),0) -> 1126576.5 | I3: =IFERROR(INDIRECT($A3&"!$N8"),0) -> 22160 | J3: =IFERROR(INDIRECT($A3&"!$N9"),0) -> 50856.87 | K3: =SUM(B3:J3) -> 4181974.4 | L3: =Febrero!D2 -> -0.0063999368 | M3: 0.024
A4: Marzo | B4: =IFERROR(INDIRECT($A4&"!$N1"),0) -> 0 | C4: =IFERROR(INDIRECT($A4&"!$N2"),0) -> 410678 | D4: =IFERROR(INDIRECT($A4&"!$N3"),0) -> 650045.56 | E4: =IFERROR(INDIRECT($A4&"!$N4"),0) -> 440171 | F4: =IFERROR(INDIRECT($A4&"!$N5"),0) -> 39142 | G4: =IFERROR(INDIRECT($A4&"!$N6"),0) -> 6336846.3 | H4: =IFERROR(INDIRECT($A4&"!$N7"),0) -> 1134591.6 | I4: =IFERROR(INDIRECT($A4&"!$N8"),0) -> 21408 | J4: =IFERROR(INDIRECT($A4&"!$N9"),0) -> 107420 | K4: =SUM(B4:J4) -> 9140302.4 | L4: =Marzo!D2 -> 0.12993873 | M4: 0.03 | O4: 5Y | P4: =TODAY()-1825 -> 44162
A5: Abril | B5: =IFERROR(INDIRECT($A5&"!$N1"),0) -> 0 | C5: =IFERROR(INDIRECT($A5&"!$N2"),0) -> 438914 | D5: =IFERROR(INDIRECT($A5&"!$N3"),0) -> 169700 | E5: =IFERROR(INDIRECT($A5&"!$N4"),0) -> 458655 | F5: =IFERROR(INDIRECT($A5&"!$N5"),0) -> 332880 | G5: =IFERROR(INDIRECT($A5&"!$N6"),0) -> 6549611.8 | H5: =IFERROR(INDIRECT($A5&"!$N7"),0) -> 2185113 | I5: =IFERROR(INDIRECT($A5&"!$N8"),0) -> 23867 | J5: =IFERROR(INDIRECT($A5&"!$N9"),0) -> 107420 | K5: =SUM(B5:J5) -> 10266161 | L5: =Abril!D2 -> 0.030982204 | M5: 0.028 | O5: HOY | P5: =TODAY() -> 45987
A6: Mayo | B6: =IFERROR(INDIRECT($A6&"!$N1"),0) -> 0 | C6: =IFERROR(INDIRECT($A6&"!$N2"),0) -> 397929 | D6: =IFERROR(INDIRECT($A6&"!$N3"),0) -> 51180 | E6: =IFERROR(INDIRECT($A6&"!$N4"),0) -> 461810 | F6: =IFERROR(INDIRECT($A6&"!$N5"),0) -> 341521.4 | G6: =IFERROR(INDIRECT($A6&"!$N6"),0) -> 6685655.9 | H6: =IFERROR(INDIRECT($A6&"!$N7"),0) -> 2205766.2 | I6: =IFERROR(INDIRECT($A6&"!$N8"),0) -> 24930.7 | J6: =IFERROR(INDIRECT($A6&"!$N9"),0) -> 29244.57 | K6: =SUM(B6:J6) -> 10198038 | L6: =Mayo!D2 -> 0.04517191 | M6: 0.0172
A7: Junio | B7: =IFERROR(INDIRECT($A7&"!$N1"),0) -> 0 | C7: =IFERROR(INDIRECT($A7&"!$N2"),0) -> 365441 | D7: =IFERROR(INDIRECT($A7&"!$N3"),0) -> 52740 | E7: =IFERROR(INDIRECT($A7&"!$N4"),0) -> 505953 | F7: =IFERROR(INDIRECT($A7&"!$N5"),0) -> 353492 | G7: =IFERROR(INDIRECT($A7&"!$N6"),0) -> 6724481.9 | H7: =IFERROR(INDIRECT($A7&"!$N7"),0) -> 3259732.2 | I7: =IFERROR(INDIRECT($A7&"!$N8"),0) -> 28000 | J7: =IFERROR(INDIRECT($A7&"!$N9"),0) -> 107420 | K7: =SUM(B7:J7) -> 11397260 | L7: =Junio!D2 -> 0.035301276 | M7: 0.016
A8: Julio | B8: =IFERROR(INDIRECT($A8&"!$N1"),0) -> 0 | C8: =IFERROR(INDIRECT($A8&"!$N2"),0) -> 414838 | D8: =IFERROR(INDIRECT($A8&"!$N3"),0) -> 54780 | E8: =IFERROR(INDIRECT($A8&"!$N4"),0) -> 574225 | F8: =IFERROR(INDIRECT($A8&"!$N5"),0) -> 396699 | G8: =IFERROR(INDIRECT($A8&"!$N6"),0) -> 6911392.9 | H8: =IFERROR(INDIRECT($A8&"!$N7"),0) -> 3375673.7 | I8: =IFERROR(INDIRECT($A8&"!$N8"),0) -> 31114.52 | J8: =IFERROR(INDIRECT($A8&"!$N9"),0) -> 107420 | K8: =SUM(B8:J8) -> 11866143 | L8: =Julio!D2 -> 0.078298801 | M8: 0.02
A9: Agosto | B9: =IFERROR(INDIRECT($A9&"!$N1"),0) -> 0 | C9: =IFERROR(INDIRECT($A9&"!$N2"),0) -> 305751.82 | D9: =IFERROR(INDIRECT($A9&"!$N3"),0) -> 51180 | E9: =IFERROR(INDIRECT($A9&"!$N4"),0) -> 683313 | F9: =IFERROR(INDIRECT($A9&"!$N5"),0) -> 340811.4 | G9: =IFERROR(INDIRECT($A9&"!$N6"),0) -> 6685655.9 | H9: =IFERROR(INDIRECT($A9&"!$N7"),0) -> 2344814 | I9: =IFERROR(INDIRECT($A9&"!$N8"),0) -> 31430 | J9: =IFERROR(INDIRECT($A9&"!$N9"),0) -> 107420 | K9: =SUM(B9:J9) -> 10550376 | L9: =Agosto!D2 -> 0.035332511
A10: Septiembre | B10: =IFERROR(INDIRECT($A10&"!$N1"),0) -> 0 | C10: =IFERROR(INDIRECT($A10&"!$N2"),0) -> 449236.8 | D10: =IFERROR(INDIRECT($A10&"!$N3"),0) -> 51180 | E10: =IFERROR(INDIRECT($A10&"!$N4"),0) -> 835525 | F10: =IFERROR(INDIRECT($A10&"!$N5"),0) -> 340811.4 | G10: =IFERROR(INDIRECT($A10&"!$N6"),0) -> 6685655.9 | H10: =IFERROR(INDIRECT($A10&"!$N7"),0) -> 1866788 | I10: =IFERROR(INDIRECT($A10&"!$N8"),0) -> 31430 | J10: =IFERROR(INDIRECT($A10&"!$N9"),0) -> 107420 | K10: =SUM(B10:J10) -> 10368047 | L10: =Septiembre!D2 -> 0.07387484
A11: Octubre | K11: =SUM(B11:J11) -> 0 | L11: 0
A12: Noviembre | K12: =SUM(B12:H12) -> 0 | L12: 0
A13: Diciembre | K13: =SUM(B13:H13) -> 0 | L13: 0
A53: =IFERROR(__xludf.DUMMYFUNCTION("IMPORTHTML(""https://www.ambito.com/contenidos/dolar-mep.html"",""table"",2)"),"#N/A") -> #N/A
A96: var i = 1; [].forEach.call(document.getElementsByTagName("table"),
A97: function(x) { console.log(i++, x); });

Sheet Transacciones
A1: Ticker | B1: Fecha Transaccion | C1: Tipo | D1: Unidades | E1: PCU | F1: PVU | G1: Total Compra | H1: Total Venta | I1: P&L | J1: P&L % | L1: Ventas | M1: Profit
A2: ALUA | B2: Enero | C2: Compra | D2: 15 | E2: 984 | F2: 0 | G2: =E2*D2 -> 14760 | H2: =F2*D2 -> 0 | I2: =IF(H2-G2<0,0,H2-G2) -> 0 | J2: =IFERROR(I2/G2,0) -> 0 | L2: =SUMIF(C2:C914,"Venta",H2:HI914) -> 6988165.1 | M2: =SUM(I2:I914) -> 271590.94
A3: BYMA | B3: Enero | C3: Compra | D3: 28 | E3: 368 | F3: 0 | G3: =E3*D3 -> 10304 | H3: =F3*D3 -> 0 | I3: =IF(H3-G3<0,0,H3-G3) -> 0 | J3: =IFERROR(I3/G3,0) -> 0
A4: CEPU | B4: Enero | C4: Compra | D4: 20 | E4: 1740 | G4: =E4*D4 -> 34800 | H4: =F4*D4 -> 0 | I4: =IF(H4-G4<0,0,H4-G4) -> 0 | J4: =IFERROR(I4/G4,0) -> 0
A5: COME | B5: Enero | C5: Compra | D5: 45 | E5: 234.25 | G5: =E5*D5 -> 10541.25 | H5: =F5*D5 -> 0 | I5: =IF(H5-G5<0,0,H5-G5) -> 0 | J5: =IFERROR(I5/G5,0) -> 0
A6: EDN | B6: Enero | C6: Compra | D6: 20 | E6: 942 | G6: =E6*D6 -> 18840 | H6: =F6*D6 -> 0 | I6: =IF(H6-G6<0,0,H6-G6) -> 0 | J6: =IFERROR(I6/G6,0) -> 0
A7: MORI | B7: Enero | C7: Compra | D7: 100 | E7: 394 | G7: =E7*D7 -> 39400 | H7: =F7*D7 -> 0 | I7: =IF(H7-G7<0,0,H7-G7) -> 0 | J7: =IFERROR(I7/G7,0) -> 0
A8: PAMP | B8: Enero | C8: Compra | D8: 20 | E8: 4200 | G8: =E8*D8 -> 84000 | H8: =F8*D8 -> 0 | I8: =IF(H8-G8<0,0,H8-G8) -> 0 | J8: =IFERROR(I8/G8,0) -> 0
A9: SEMI | B9: Enero | C9: Compra | D9: 7160 | E9: 40 | G9: =E9*D9 -> 286400 | H9: =F9*D9 -> 0 | I9: =IF(H9-G9<0,0,H9-G9) -> 0 | J9: =IFERROR(I9/G9,0) -> 0
A10: TGNO4 | B10: Enero | C10: Compra | D10: 10 | E10: 4435 | G10: =E10*D10 -> 44350 | H10: =F10*D10 -> 0 | I10: =IF(H10-G10<0,0,H10-G10) -> 0 | J10: =IFERROR(I10/G10,0) -> 0
A11: TXAR | B11: Enero | C11: Compra | D11: 23 | E11: 963 | G11: =E11*D11 -> 22149 | H11: =F11*D11 -> 0 | I11: =IF(H11-G11<0,0,H11-G11) -> 0 | J11: =IFERROR(I11/G11,0) -> 0
A12: AE38 | B12: Enero | C12: Compra | D12: 60 | E12: 740 | G12: =E12*D12 -> 44400 | H12: =F12*D12 -> 0 | I12: =IF(H12-G12<0,0,H12-G12) -> 0 | J12: =IFERROR(I12/G12,0) -> 0
A13: AL29 | B13: Enero | C13: Compra | D13: 60 | E13: 826 | G13: =E13*D13 -> 49560 | H13: =F13*D13 -> 0 | I13: =IF(H13-G13<0,0,H13-G13) -> 0 | J13: =IFERROR(I13/G13,0) -> 0
A14: AL30 | B14: Enero | C14: Compra | D14: 163 | E14: 770 | G14: =E14*D14 -> 125510 | H14: =F14*D14 -> 0 | I14: =IF(H14-G14<0,0,H14-G14) -> 0 | J14: =IFERROR(I14/G14,0) -> 0
A15: AMZN | B15: Enero | C15: Compra | D15: 45 | E15: 1895 | G15: =E15*D15 -> 85275 | H15: =F15*D15 -> 0 | I15: =IF(H15-G15<0,0,H15-G15) -> 0 | J15: =IFERROR(I15/G15,0) -> 0
... A36: EDN | B36: Enero | C36: Compra | D36: 5 | E36: 2585 | G36: =E36*D36 -> 12925 | H36: =F36*D36 -> 0 | I36: =IF(H36-G36<0,0,H36-G36) -> 0 | J36: =IFERROR(I36/G36,0) -> 0
A37: S14F5 | B37: Enero | C37: Venta | D37: 17014 | E37: 1.16 | F37: 1.1755 | G37: =E37*D37 -> 19736.24 | H37: =F37*D37 -> 19999.957 | I37: =IF(H37-G37<0,0,H37-G37) -> 263.717 | J37: =IFERROR(I37/G37,0) -> 0.013362069
A38: S17E5 | B38: Enero | C38: Venta | D38: 87209 | E38: 1.256 | F38: 1.31 | G38: =E38*D38 -> 109534.5 | H38: =F38*D38 -> 114243.79 | I38: =IF(H38-G38<0,0,H38-G38) -> 4709.286 | J38: =IFERROR(I38/G38,0) -> 0.042993631
A39: S28F5 | B39: Enero | C39: Compra | D39: 74389 | E39: 1.5 | G39: =E39*D39 -> 111583.5 | H39: =F39*D39 -> 0 | I39: =IF(H39-G39<0,0,H39-G39) -> 0 | J39: =IFERROR(I39/G39,0) -> 0
A40: MR39O | B40: Febrero | C40: Compra | D40: 12 | E40: 1169.9 | G40: =E40*D40 -> 14038.8 | H40: =F40*D40 -> 0 | I40: =IF(H40-G40<0,0,H40-G40) -> 0 | J40: =IFERROR(I40/G40,0) -> 0
A41: Allaria Diversificado Clase A | B41: Febrero | C41: Venta | D41: 3862 | E41: 104.14 | F41: 113.16 | G41: =E41*D41 -> 402188.68 | H41: =F41*D41 -> 437023.92 | I41: =IF(H41-G41<0,0,H41-G41) -> 34835.24 | J41: =IFERROR(I41/G41,0) -> 0.086614173
A42: S16A5 | B42: Febrero | C42: Compra | D42: 391711 | E42: 1.27 | G42: =E42*D42 -> 497472.97 | H42: =F42*D42 -> 0 | I42: =IF(H42-G42<0,0,H42-G42) -> 0 | J42: =IFERROR(I42/G42,0) -> 0
A43: T13F6 | B43: Febrero | C43: Compra | D43: 444714 | E43: 1.11175 | G43: =E43*D43 -> 494410.79 | H43: =F43*D43 -> 0 | I43: =IF(H43-G43<0,0,H43-G43) -> 0 | J43: =IFERROR(I43/G43,0) -> 0
A44: S28F5 | B44: Febrero | C44: Venta | D44: 74389 | E44: 1.5 | F44: 1.5828 | G44: =E44*D44 -> 111583.5 | H44: =F44*D44 -> 117742.91 | I44: =IF(H44-G44<0,0,H44-G44) -> 6159.4092 | J44: =IFERROR(I44/G44,0) -> 0.0552
A45: S14M5 | B45: Febrero | C45: Compra | D45: 493143 | E45: 1.25 | G45: =E45*D45 -> 616428.75 | H45: =F45*D45 -> 0 | I45: =IF(H45-G45<0,0,H45-G45) -> 0 | J45: =IFERROR(I45/G45,0) -> 0
A46: S14M5 | B46: Marzo | C46: Compra | D46: 398464 | E46: 1.26482 | G46: =E46*D46 -> 503985.24 | H46: =F46*D47 -> 0 | I46: =IF(H46-G46<0,0,H46-G46) -> 0 | J46: =IFERROR(I46/G46,0) -> 0
A47: S16A5 | B47: Marzo | C47: Compra | D47: 785211 | E47: 1.2837 | G47: =E47*D47 -> 1007975.4 | H47: =F47*D48 -> 0 | I47: =IF(H47-G47<0,0,H47-G47) -> 0 | J47: =IFERROR(I47/G47,0) -> 0
A48: TGNO4 | B48: Marzo | C48: Venta | D48: 10 | E48: 4435 | F48: 3450 | G48: =E48*D48 -> 44350 | H48: =F48*D48 -> 34500 | I48: =IF(H48-G48<0,0,H48-G48) -> 0 | J48: =IFERROR(I48/G48,0) -> 0
A49: AL29 | B49: Marzo | C49: Venta | D49: 60 | E49: 826 | F49: 854 | G49: =E49*D49 -> 49560 | H49: =F49*D49 -> 51240 | I49: =IF(H49-G49<0,0,H49-G49) -> 1680 | J49: =IFERROR(I49/G49,0) -> 0.033898305
A50: Max Ahorro Pesos Clase A | B50: Marzo | C50: Compra | D50: 93074.373 | E50: 5.34195 | G50: =E50*D50 -> 497198.65 | H50: =F50*D50 -> 0 | I50: =IF(H50-G50<0,0,H50-G50) -> 0 | J50: =IFERROR(I50/G50,0) -> 0
A51: Schroder Renta Plus Clase A | B51: Marzo | C51: Compra | D51: 6370.6252 | E51: 78.473735 | G51: =E51*D51 -> 499926.75 | H51: =F51*D51 -> 0 | I51: =IF(H51-G51<0,0,H51-G51) -> 0 | J51: =IFERROR(I51/G51,0) -> 0
A52: Fima Premium | B52: Marzo | C52: Compra | D52: 5039.09 | E52: 59.534602 | G52: =E52*D52 -> 300000.22 | H52: =F52*D52 -> 0 | I52: =IF(H52-G52<0,0,H52-G52) -> 0 | J52: =IFERROR(I52/G52,0) -> 0
A53: Fima Ahorro Plus | B53: Marzo | C53: Compra | D53: 9615.98 | E53: 103.99364 | G53: =E53*D53 -> 1000000.7 | H53: =F53*D53 -> 0 | I53: =IF(H53-G53<0,0,H53-G53) -> 0 | J53: =IFERROR(I53/G53,0) -> 0
A54: Fima Ahorro Peso | B54: Marzo | C54: Compra | D54: 2374.82 | E54: 421.08574 | G54: =E54*D54 -> 1000002.8 | H54: =F54*D54 -> 0 | I54: =IF(H54-G54<0,0,H54-G54) -> 0 | J54: =IFERROR(I54/G54,0) -> 0
A55: S14M5 | B55: Marzo | C55: Venta | D55: 891607 | E55: 1.25 | F55: 1.26 | G55: =E55*D55 -> 1114508.8 | H55: =F55*D55 -> 1123424.8 | I55: =IF(H55-G55<0,0,H55-G55) -> 8916.07 | J55: =IFERROR(I55/G55,0) -> 0.008
A56: S28A5 | B56: Marzo | C56: Compra | D56: 394448 | E56: 1.266 | G56: =E56*D56 -> 499371.17 | H56: =F56*D56 -> 0 | I56: =IF(H56-G56<0,0,H56-G56) -> 0 | J56: =IFERROR(I56/G56,0) -> 0
A57: S16Y5 | B57: Marzo | C57: Compra | D57: 476337 | E57: 1.306 | G57: =E57*D57 -> 622096.12 | H57: =F57*D57 -> 0 | I57: =IF(H57-G57<0,0,H57-G57) -> 0 | J57: =IFERROR(I57/G57,0) -> 0
A58: Adcap Ahorro Pesos Clase A | B58: Marzo | C58: Compra | D58: 38715.043 | E58: 12.9 | G58: =E58*D58 -> 499424.06 | H58: =F58*D58 -> 0 | I58: =IF(H58-G58<0,0,H58-G58) -> 0 | J58: =IFERROR(I58/G58,0) -> 0
A59: TF36 | B59: Abril | C59: Venta | D59: 444714 | E59: 1.11175 | F59: 1.047 | G59: =E59*D59 -> 494410.79 | H59: =F59*D59 -> 465615.56 | I59: =IF(H59-G59<0,0,H59-G59) -> 0 | J59: =IFERROR(I59/G59,0) -> 0
A60: RUCDD | B60: Abril | C60: Compra | D60: 99 | E60: 1315.0625 | G60: =E60*D60 -> 130191.19 | H60: =F60*D60 -> 0 | I60: =IF(H60-G60<0,0,H60-G60) -> 0 | J60: =IFERROR(I60/G60,0) -> 0
...

Sheet Septiembre
A1: Portfolio De Inversiones | C1: P&L | D1: P&L % | E1: Valor Medio Total | F1: Valor Portolio | G1: Efectivo | H1: Medio+Efectivo | I1: Portfolio+Efectivo | M1: Opc/Futuros | N1: =SUMIF(B4:B1001,M1,G4:G1001) -> 0
C2: =SUM(I5:I1001) -> 705857.1 | D2: =(F2/E2)-1 -> 0.07387484 | E2: =SUM(G5:G1001) -> 9554769.9 | F2: =SUM(H5:H1001) -> 10260627 | G2: =N9+SUMIF(Transacciones!C2:C1001,"Venta",Transacciones!I2:I1001) -> 300653.56 | H2: =E2+G2 -> 9855423.5 | I2: =F2+G2 -> 10561281 | M2: Acciones | N2: =SUMIF($B$5:B1001,M2,$H$5:H1001) -> 449236.8
M3: Bonos | N3: =SUMIF($B$5:B1002,M3,$H$5:H1002) -> 51180
A4: Ticker | B4: Tipo | C4: Cantidad | D4: % Portfolio | E4: Costo medio | F4: Precio Actual | G4: Valor Medio | H4: Valor de Mercado | I4: P&L | J4: P&L % | K4: Broker | M4: Cedear | N4: =SUMIF($B$5:B1003,M4,$H$5:H1003) -> 835525 | P4: P&L Julio/Junio
A5: ALUA | B5: Acciones | C5: =SUMIFS(Transacciones!$D$2:$D1001,Transacciones!$A$2:$A1001,A5,Transacciones!$C$2:$C1001,"Compra")-SUMIFS(Transacciones!$D$2:$D1001,Transacciones!$A$2:$A1001,A5,Transacciones!$C$2:$C1001,"Venta") -> 15 | D5: =(H5/$F$2) -> 0.001476518 | E5: =IFERROR((SUMIFS(Transacciones!$G$2:$G1001,Transacciones!$A$2:$A1001,A5,Transacciones!$C$2:$C1001,"Compra")-SUMIFS(Transacciones!$G$2:$G1001,Transacciones!$A$2:$A1001,A5,Transacciones!$C$2:$C1001,"Venta"))/C5,0) -> 984 | F5: =IFERROR(__xludf.DUMMYFUNCTION("GOOGLEFINANCE(""BCBA:""&A5,""price"")"),1010.0) -> 1010 | G5: =C5*E5 -> 14760 | H5: =F5*C5 -> 15150 | I5: =H5-G5 -> 390 | J5: =IFERROR(I5/G5,0) -> 0.026422764 | K5: Eco | M5: ON | N5: =SUMIF($B$5:B1004,M5,$H$5:H1004) -> 340811.4 | P5: =SUM(I5-Junio!I5) -> 4410
A6: BYMA | B6: Acciones | C6: =SUMIFS(Transacciones!$D$2:$D1001,Transacciones!$A$2:$A1001,A6,Transacciones!$C$2:$C1001,"Compra")-SUMIFS(Transacciones!$D$2:$D1001,Transacciones!$A$2:$A1001,A6,Transacciones!$C$2:$C1001,"Venta") -> 30 | D6: =(H6/$F$2) -> 0.00085009425 | E6: =IFERROR((SUMIFS(Transacciones!$G$2:$G1001,Transacciones!$A$2:$A1001,A6,Transacciones!$C$2:$C1001,"Compra")-SUMIFS(Transacciones!$G$2:$G1001,Transacciones!$A$2:$A1001,A6,Transacciones!$C$2:$C1001,"Venta"))/C6,0) -> 371.26667 | F6: =IFERROR(__xludf.DUMMYFUNCTION("GOOGLEFINANCE(""BCBA:""&A6,""price"")"),290.75) -> 290.75 | G6: =C6*E6 -> 11138 | H6: =F6*C6 -> 8722.5 | I6: =H6-G6 -> -2415.5 | J6: =IFERROR(I6/G6,0) -> -0.21687017 | K6: Eco | M6: FCI | N6: =SUMIF($B$5:B1005,M6,$H$5:H1005) -> 6685655.9 | P6: =SUM(I6-Junio!I6) -> 2962.5
A7: CEPU | B7: Acciones | C7: =SUMIFS(Transacciones!$D$2:$D1001,Transacciones!$A$2:$A1001,A7,Transacciones!$C$2:$C1001,"Compra")-SUMIFS(Transacciones!$D$2:$D1001,Transacciones!$A$2:$A1001,A7,Transacciones!$C$2:$C1001,"Venta") -> 20 | D7: =(H7/$F$2) -> 0.0043662049 | E7: =IFERROR((SUMIFS(Transacciones!$G$2:$G1001,Transacciones!$A$2:$A1001,A7,Transacciones!$C$2:$C1001,"Compra")-SUMIFS(Transacciones!$G$2:$G1001,Transacciones!$A$2:$A1001,A7,Transacciones!$C$2:$C1001,"Venta"))/C7,0) -> 1740 | F7: =IFERROR(__xludf.DUMMYFUNCTION("GOOGLEFINANCE(""BCBA:""&A7,""price"")"),2240.0) -> 2240 | G7: =C7*E7 -> 34800 | H7: =F7*C7 -> 44800 | I7: =H7-G7 -> 10000 | J7: =IFERROR(I7/G7,0) -> 0.28735632 | K7: Eco | M7: Letras | N7: =SUMIF($B$5:B1006,M7,$H$5:H1006) -> 1866788 | P7: =SUM(I7-Junio!I7) -> 16400
A8: COME | B8: Acciones | C8: =SUMIFS(Transacciones!$D$2:$D1001,Transacciones!$A$2:$A1001,A8,Transacciones!$C$2:$C1001,"Compra")-SUMIFS(Transacciones!$D$2:$D1001,Transacciones!$A$2:$A1001,A8,Transacciones!$C$2:$C1001,"Venta") -> 46 | D8: =(H8/$F$2) -> 0.00033085697 | E8: =IFERROR((SUMIFS(Transacciones!$G$2:$G1001,Transacciones!$A$2:$A1001,A8,Transacciones!$C$2:$C1001,"Compra")-SUMIFS(Transacciones!$G$2:$G1001,Transacciones!$A$2:$A1001,A8,Transacciones!$C$2:$C1001,"Venta"))/C8,0) -> 232.2337 | F8: =IFERROR(__xludf.DUMMYFUNCTION("GOOGLEFINANCE(""BCBA:""&A8,""price"")"),73.8) -> 73.8 | G8: =C8*E8 -> 10682.75 | H8: =F8*C8 -> 3394.8 | I8: =H8-G8 -> -7287.95 | J8: =IFERROR(I8/G8,0) -> -0.68221666 | K8: Eco | M8: Cripto | N8: =SUMIF($B$5:B1007,M8,$H$5:H1007) -> 31430 | P8: =SUM(I8-Junio!I8) -> -2033.2
A9: EDN | B9: Acciones | C9: =SUMIFS(Transacciones!$D$2:$D1001,Transacciones!$A$2:$A1001,A9,Transacciones!$C$2:$C1001,"Compra")-SUMIFS(Transacciones!$D$2:$D1001,Transacciones!$A$2:$A1001,A9,Transacciones!$C$2:$C1001,"Venta") -> 25 | D9: =(H9/$F$2) -> 0.0038983972 | E9: =IFERROR((SUMIFS(Transacciones!$G$2:$G1001,Transacciones!$A$2:$A1001,A9,Transacciones!$C$2:$C1001,"Compra")-SUMIFS(Transacciones!$G$2:$G1001,Transacciones!$A$2:$A1001,A9,Transacciones!$C$2:$C1001,"Venta"))/C9,0) -> 1270.6 | F9: =IFERROR(__xludf.DUMMYFUNCTION("GOOGLEFINANCE(""BCBA:""&A9,""price"")"),1600.0) -> 1600 | G9: =C9*E9 -> 31765 | H9: =F9*C9 -> 40000 | I9: =H9-G9 -> 8235 | J9: =IFERROR(I9/G9,0) -> 0.2592476 | K9: Eco | M9: Efectivo | N9: 107420 | P9: =SUM(I9-Junio!I9) -> 1875
A10: MORI | B10: Acciones | C10: =SUMIFS(Transacciones!$D$2:$D1001,Transacciones!$A$2:$A1001,A10,Transacciones!$C$2:$C1001,"Compra")-SUMIFS(Transacciones!$D$2:$D1001,Transacciones!$A$2:$A1001,A10,Transacciones!$C$2:$C1001,"Venta") -> 100 | D10: =(H10/$F$2) -> 0.00047268067 | E10: =IFERROR((SUMIFS(Transacciones!$G$2:$G1001,Transacciones!$A$2:$A1001,A10,Transacciones!$C$2:$C1001,"Compra")-SUMIFS(Transacciones!$G$2:$G1001,Transacciones!$A$2:$A1001,A10,Transacciones!$C$2:$C1001,"Venta"))/C10,0) -> 394 | F10: =IFERROR(__xludf.DUMMYFUNCTION("GOOGLEFINANCE(""BCBA:""&A10,""price"")"),48.5) -> 48.5 | G10: =C10*E10 -> 39400 | H10: =F10*C10 -> 4850 | I10: =H10-G10 -> -34550 | J10: =IFERROR(I10/G10,0) -> -0.87690355 | K10: Eco | M10: Total | N10: =SUM(N1:N9) -> 10368047
A11: PAMP | B11: Acciones | C11: =SUMIFS(Transacciones!$D$2:$D1001,Transacciones!$A$2:$A1001,A11,Transacciones!$C$2:$C1001,"Compra")-SUMIFS(Transacciones!$D$2:$D1001,Transacciones!$A$2:$A1001,A11,Transacciones!$C$2:$C1001,"Venta") -> 20 | D11: =(H11/$F$2) -> 0.010515927 | E11: =IFERROR((SUMIFS(Transacciones!$G$2:$G1001,Transacciones!$A$2:$A1001,A11,Transacciones!$C$2:$C1001,"Compra")-SUMIFS(Transacciones!$G$2:$G1001,Transacciones!$A$2:$A1001,A11,Transacciones!$C$2:$C1001,"Venta"))/C11,0) -> 4200 | F11: =IFERROR(__xludf.DUMMYFUNCTION("GOOGLEFINANCE(""BCBA:""&A11,""price"")"),5395.0) -> 5395 | G11: =C11*E11 -> 84000 | H11: =F11*C11 -> 107900 | I11: =H11-G11 -> 23900 | J11: =IFERROR(I11/G11,0) -> 0.28452381 | K11: Eco
A12: SEMI | B12: Acciones | C12: =SUMIFS(Transacciones!$D$2:$D1001,Transacciones!$A$2:$A1001,A12,Transacciones!$C$2:$C1001,"Compra")-SUMIFS(Transacciones!$D$2:$D1001,Transacciones!$A$2:$A1001,A12,Transacciones!$C$2:$C1001,"Venta") -> 7660 | D12: =(H12/$F$2) -> 0.020082009 | E12: =IFERROR((SUMIFS(Transacciones!$G$2:$G1001,Transacciones!$A$2:$A1001,A12,Transacciones!$C$2:$C1001,"Compra")-SUMIFS(Transacciones!$G$2:$G1001,Transacciones!$A$2:$A1001,A12,Transacciones!$C$2:$C1001,"Venta"))/C12,0) -> 40 | F12: =IFERROR(__xludf.DUMMYFUNCTION("GOOGLEFINANCE(""BCBA:""&A12,""price"")"),26.9) -> 26.9 | G12: =C12*E12 -> 306400 | H12: =F12*C12 -> 206054 | I12: =H12-G12 -> -100346 | J12: =IFERROR(I12/G12,0) -> -0.3275 | K12: Eco | M12: Eco | N12: =SUMIF($K$5:$K1001,M12,$H$5:$H1001) -> 1365009.8
A13: TXAR | B13: Acciones | C13: =SUMIFS(Transacciones!$D$2:$D1001,Transacciones!$A$2:$A1001,A13,Transacciones!$C$2:$C1001,"Compra")-SUMIFS(Transacciones!$D$2:$D1001,Transacciones!$A$2:$A1001,A13,Transacciones!$C$2:$C1001,"Venta") -> 23 | D13: =(H13/$F$2) -> 0.0017899004 | E13: =IFERROR((SUMIFS(Transacciones!$G$2:$G1001,Transacciones!$A$2:$A1001,A13,Transacciones!$C$2:$C1001,"Compra")-SUMIFS(Transacciones!$G$2:$G1001,Transacciones!$A$2:$A1001,A13,Transacciones!$C$2:$C1001,"Venta"))/C13,0) -> 963 | F13: =IFERROR(__xludf.DUMMYFUNCTION("GOOGLEFINANCE(""BCBA:""&A13,""price"")"),798.5) -> 798.5 | G13: =C13*E13 -> 22149 | H13: =F13*C13 -> 18365.5 | I13: =H13-G13 -> -3783.5 | J13: =IFERROR(I13/G13,0) -> -0.17082035 | K13: Eco | M13: Ppi | N13: =SUMIF($K$5:$K1002,M13,$H$5:$H1002) -> 5729735.1
A14: AMZN | B14: Cedear | C14: =SUMIFS(Transacciones!$D$2:$D1001,Transacciones!$A$2:$A1001,A14,Transacciones!$C$2:$C1001,"Compra")-SUMIFS(Transacciones!$D$2:$D1001,Transacciones!$A$2:$A1001,A14,Transacciones!$C$2:$C1001,"Venta") -> 45 | D14: =(H14/$F$2) -> 0.010780043 | E14: =IFERROR((SUMIFS(Transacciones!$G$2:$G1001,Transacciones!$A$2:$A1001,A14,Transacciones!$C$2:$C1001,"Compra")-SUMIFS(Transacciones!$G$2:$G1001,Transacciones!$A$2:$A1001,A14,Transacciones!$C$2:$C1001,"Venta"))/C14,0) -> 1895 | F14: =IFERROR(__xludf.DUMMYFUNCTION("GOOGLEFINANCE(""BCBA:""&A14,""price"")"),2458.0) -> 2458 | G14: =C14*E14 -> 85275 | H14: =F14*C14 -> 110610 | I14: =H14-G14 -> 25335 | J14: =IFERROR(I14/G14,0) -> 0.29709763 | K14: Eco | M14: Binance | N14: =SUMIF($K$5:$K1003,M14,$H$5:$H1003) -> 31430
A15: BABA | B15: Cedear | C15: =SUMIFS(Transacciones!$D$2:$D1001,Transacciones!$A$2:$A1001,A15,Transacciones!$C$2:$C1001,"Compra")-SUMIFS(Transacciones!$D$2:$D1001,Transacciones!$A$2:$A1001,A15,Transacciones!$C$2:$C1001,"Venta") -> 1 | D15: =(H15/$F$2) -> 0.0026333673 | E15: =IFERROR((SUMIFS(Transacciones!$G$2:$G1001,Transacciones!$A$2:$A1001,A15,Transacciones!$C$2:$C1001,"Compra")-SUMIFS(Transacciones!$G$2:$G1001,Transacciones!$A$2:$A1001,A15,Transacciones!$C$2:$C1001,"Venta"))/C15,0) -> 11400 | F15: =IFERROR(__xludf.DUMMYFUNCTION("GOOGLEFINANCE(""BCBA:""&A15,""price"")"),27020.0) -> 27020 | G15: =C15*E15 -> 11400 | H15: =F15*C15 -> 27020 | I15: =H15-G15 -> 15620 | J15: =IFERROR(I15/G15,0) -> 1.3701754 | K15: Eco | M15: Galicia | N15: =SUMIF($K$5:$K1004,M15,$H$5:$H1004) -> 3134452.1
A16: CDE | B16: Cedear | C16: =SUMIFS(Transacciones!$D$2:$D1001,Transacciones!$A$2:$A1001,A16,Transacciones!$C$2:$C1001,"Compra")-SUMIFS(Transacciones!$D$2:$D1001,Transacciones!$A$2:$A1001,A16,Transacciones!$C$2:$C1001,"Venta") -> 5 | D16: =(H16/$F$2) -> 0.0100335 | E16: =IFERROR((SUMIFS(Transacciones!$G$2:$G1001,Transacciones!$A$2:$A1001,A16,Transacciones!$C$2:$C1001,"Compra")-SUMIFS(Transacciones!$G$2:$G1001,Transacciones!$A$2:$A1001,A16,Transacciones!$C$2:$C1001,"Venta"))/C16,0) -> 7400 | F16: 20590 | G16: =C16*E16 -> 37000 | H16: =F16*C16 -> 102950 | I16: =H16-G16 -> 65950 | J16: =IFERROR(I16/G16,0) -> 1.7824324 | K16: Eco | M16: Efectivo | N16: 107420
A17: ETHA | B17: Cedear | C17: 5 | D17: =(H17/$F$2) -> 0.0045367598 | E17: =IFERROR((SUMIFS(Transacciones!$G$2:$G1001,Transacciones!$A$2:$A1001,A17,Transacciones!$C$2:$C1001,"Compra")-SUMIFS(Transacciones!$G$2:$G1001,Transacciones!$A$2:$A1001,A17,Transacciones!$C$2:$C1001,"Venta"))/C17,0) -> 5970 | F17: 9310 | G17: =C17*E17 -> 29850 | H17: =F17*C17 -> 46550 | I17: =H17-G17 -> 16700 | J17: =IFERROR(I17/G17,0) -> 0.55946399 | K17: Eco | M17: Total | N17: =SUM(N12:N16) -> 10368047
A18: GOOGL | B18: Cedear | C18: =SUMIFS(Transacciones!$D$2:$D1001,Transacciones!$A$2:$A1001,A18,Transacciones!$C$2:$C1001,"Compra")-SUMIFS(Transacciones!$D$2:$D1001,Transacciones!$A$2:$A1001,A18,Transacciones!$C$2:$C1001,"Venta") -> 25 | D18: =(H18/$F$2) -> 0.020515315 | E18: =IFERROR((SUMIFS(Transacciones!$G$2:$G1001,Transacciones!$A$2:$A1001,A18,Transacciones!$C$2:$C1001,"Compra")-SUMIFS(Transacciones!$G$2:$G1001,Transacciones!$A$2:$A1001,A18,Transacciones!$C$2:$C1001,"Venta"))/C18,0) -> 3995 | F18: =IFERROR(__xludf.DUMMYFUNCTION("GOOGLEFINANCE(""BCBA:""&A18,""price"")"),8420.0) -> 8420 | G18: =C18*E18 -> 99875 | H18: =F18*C18 -> 210500 | I18: =H18-G18 -> 110625 | J18: =IFERROR(I18/G18,0) -> 1.1076345 | K18: Eco
A19: IBM | B19: Cedear | C19: =SUMIFS(Transacciones!$D$2:$D1001,Transacciones!$A$2:$A1001,A19,Transacciones!$C$2:$C1001,"Compra")-SUMIFS(Transacciones!$D$2:$D1001,Transacciones!$A$2:$A1001,A19,Transacciones!$C$2:$C1001,"Venta") -> 1 | D19: =(H19/$F$2) -> 0.0030232071 | E19: =IFERROR((SUMIFS(Transacciones!$G$2:$G1001,Transacciones!$A$2:$A1001,A19,Transacciones!$C$2:$C1001,"Compra")-SUMIFS(Transacciones!$G$2:$G1001,Transacciones!$A$2:$A1001,A19,Transacciones!$C$2:$C1001,"Venta"))/C19,0) -> 17850 | F19: =IFERROR(__xludf.DUMMYFUNCTION("GOOGLEFINANCE(""BCBA:""&A19,""price"")"),31020.0) -> 31020 | G19: =C19*E19 -> 17850 | H19: =F19*C19 -> 31020 | I19: =H19-G19 -> 13170 | J19: =IFERROR(I19/G19,0) -> 0.73781513 | K19: Eco
A20: KO | B20: Cedear | C20: =SUMIFS(Transacciones!$D$2:$D1001,Transacciones!$A$2:$A1001,A20,Transacciones!$C$2:$C1001,"Compra")-SUMIFS(Transacciones!$D$2:$D1001,Transacciones!$A$2:$A1001,A20,Transacciones!$C$2:$C1001,"Venta") -> 1 | D20: =(H20/$F$2) -> 0.0021675089 | E20: =IFERROR((SUMIFS(Transacciones!$G$2:$G1001,Transacciones!$A$2:$A1001,A20,Transacciones!$C$2:$C1001,"Compra")-SUMIFS(Transacciones!$G$2:$G1001,Transacciones!$A$2:$A1001,A20,Transacciones!$C$2:$C1001,"Venta"))/C20,0) -> 15000 | F20: =IFERROR(__xludf.DUMMYFUNCTION("GOOGLEFINANCE(""BCBA:""&A20,""price"")"),22240.0) -> 22240 | G20: =C20*E20 -> 15000 | H20: =F20*C20 -> 22240 | I20: =H20-G20 -> 7240 | J20: =IFERROR(I20/G20,0) -> 0.48266667 | K20: Eco
A21: LAC | B21: Cedear | C21: =SUMIFS(Transacciones!$D$2:$D1001,Transacciones!$A$2:$A1001,A21,Transacciones!$C$2:$C1001,"Compra")-SUMIFS(Transacciones!$D$2:$D1001,Transacciones!$A$2:$A1001,A21,Transacciones!$C$2:$C1001,"Venta") -> 9 | D21: =(H21/$F$2) -> 0.0069864152 | E21: =IFERROR((SUMIFS(Transacciones!$G$2:$G1001,Transacciones!$A$2:$A1001,A21,Transacciones!$C$2:$C1001,"Compra")-SUMIFS(Transacciones!$G$2:$G1001,Transacciones!$A$2:$A1001,A21,Transacciones!$C$2:$C1001,"Venta"))/C21,0) -> 3655 | F21: =IFERROR(__xludf.DUMMYFUNCTION("GOOGLEFINANCE(""BCBA:""&A21,""price"")"),7965.0) -> 7965 | G21: =C21*E21 -> 32895 | H21: =F21*C21 -> 71685 | I21: =H21-G21 -> 38790 | J21: =IFERROR(I21/G21,0) -> 1.1792066 | K21: Eco
A22: MSFT | B22: Cedear | C22: =SUMIFS(Transacciones!$D$2:$D1001,Transacciones!$A$2:$A1001,A22,Transacciones!$C$2:$C1001,"Compra")-SUMIFS(Transacciones!$D$2:$D1001,Transacciones!$A$2:$A1001,A22,Transacciones!$C$2:$C1001,"Venta") -> 1 | D22: =(H22/$F$2) -> 0.0024199301 | E22: =IFERROR((SUMIFS(Transacciones!$G$2:$G1001,Transacciones!$A$2:$A1001,A22,Transacciones!$C$2:$C1001,"Compra")-SUMIFS(Transacciones!$G$2:$G1001,Transacciones!$A$2:$A1001,A22,Transacciones!$C$2:$C1001,"Venta"))/C22,0) -> 17775 | F22: =IFERROR(__xludf.DUMMYFUNCTION("GOOGLEFINANCE(""BCBA:""&A22,""price"")"),24830.0) -> 24830 | G22: =C22*E22 -> 17775 | H22: =F22*C22 -> 24830 | I22: =H22-G22 -> 7055 | J22: =IFERROR(I22/G22,0) -> 0.39690577 | K22: Eco
A23: PFE | B23: Cedear | C23: =SUMIFS(Transacciones!$D$2:$D1001,Transacciones!$A$2:$A1001,A23,Transacciones!$C$2:$C1001,"Compra")-SUMIFS(Transacciones!$D$2:$D1001,Transacciones!$A$2:$A1001,A23,Transacciones!$C$2:$C1001,"Venta") -> 1 | D23: =(H23/$F$2) -> 0.00095803112 | E23: =IFERROR((SUMIFS(Transacciones!$G$2:$G1001,Transacciones!$A$2:$A1001,A23,Transacciones!$C$2:$C1001,"Compra")-SUMIFS(Transacciones!$G$2:$G1001,Transacciones!$A$2:$A1001,A23,Transacciones!$C$2:$C1001,"Venta"))/C23,0) -> 7790 | F23: =IFERROR(__xludf.DUMMYFUNCTION("GOOGLEFINANCE(""BCBA:""&A23,""price"")"),9830.0) -> 9830 | G23: =C23*E23 -> 7790 | H23: =F23*C23 -> 9830 | I23: =H23-G23 -> 2040 | J23: =IFERROR(I23/G23,0) -> 0.2618742 | K23: Eco
A24: SPY | B24: Cedear | C24: =SUMIFS(Transacciones!$D$2:$D1001,Transacciones!$A$2:$A1001,A24,Transacciones!$C$2:$C1001,"Compra")-SUMIFS(Transacciones!$D$2:$D1001,Transacciones!$A$2:$A1001,A24,Transacciones!$C$2:$C1001,"Venta") -> 2 | D24: =(H24/$F$2) -> 0.010145579 | E24: =IFERROR((SUMIFS(Transacciones!$G$2:$G1001,Transacciones!$A$2:$A1001,A24,Transacciones!$C$2:$C1001,"Compra")-SUMIFS(Transacciones!$G$2:$G1001,Transacciones!$A$2:$A1001,A24,Transacciones!$C$2:$C1001,"Venta"))/C24,0) -> 35825 | F24: =IFERROR(__xludf.DUMMYFUNCTION("GOOGLEFINANCE(""BCBA:""&A24,""price"")"),52050.0) -> 52050 | G24: =C24*E24 -> 71650 | H24: =F24*C24 -> 104100 | I24: =H24-G24 -> 32450 | J24: =IFERROR(I24/G24,0) -> 0.45289602 | K24: Eco
A25: VIST | B25: Cedear | C25: =SUMIFS(Transacciones!$D$2:$D1001,Transacciones!$A$2:$A1001,A25,Transacciones!$C$2:$C1001,"Compra")-SUMIFS(Transacciones!$D$2:$D1001,Transacciones!$A$2:$A1001,A25,Transacciones!$C$2:$C1001,"Venta") -> 3 | D25: =(H25/$F$2) -> 0.0072305523 | E25: =IFERROR((SUMIFS(Transacciones!$G$2:$G1001,Transacciones!$A$2:$A1001,A25,Transacciones!$C$2:$C1001,"Compra")-SUMIFS(Transacciones!$G$2:$G1001,Transacciones!$A$2:$A1001,A25,Transacciones!$C$2:$C1001,"Venta"))/C25,0) -> 21041.667 | F25: =IFERROR(__xludf.DUMMYFUNCTION("GOOGLEFINANCE(""BCBA:""&A25,""price"")"),24730.0) -> 24730 | G25: =C25*E25 -> 63125 | H25: =F25*C25 -> 74190 | I25: =H25-G25 -> 11065 | J25: =IFERROR(I25/G25,0) -> 0.17528713 | K25: Eco
A26: AE38 | B26: Bonos | C26: =SUMIFS(Transacciones!$D$2:$D1001,Transacciones!$A$2:$A1001,A26,Transacciones!$C$2:$C1001,"Compra")-SUMIFS(Transacciones!$D$2:$D1001,Transacciones!$A$2:$A1001,A26,Transacciones!$C$2:$C1001,"Venta") -> 60 | D26: =(H26/$F$2) -> 0.0049879993 | E26: =IFERROR((SUMIFS(Transacciones!$G$2:$G1001,Transacciones!$A$2:$A1001,A26,Transacciones!$C$2:$C1001,"Compra")-SUMIFS(Transacciones!$G$2:$G1001,Transacciones!$A$2:$A1001,A26,Transacciones!$C$2:$C1001,"Venta"))/C26,0) -> 740 | F26: 853 | G26: =C26*E26 -> 44400 | H26: =F26*C26 -> 51180 | I26: =H26-G26 -> 6780 | J26: =IFERROR(I26/G26,0) -> 0.1527027 | K26: Eco
A27: YMCJO | B27: ON | C27: =SUMIFS(Transacciones!$D$2:$D1001,Transacciones!$A$2:$A1001,A27,Transacciones!$C$2:$C1001,"Compra")-SUMIFS(Transacciones!$D$2:$D1001,Transacciones!$A$2:$A1001,A27,Transacciones!$C$2:$C1001,"Venta") -> 26 | D27: =(H27/$F$2) -> 0.0028329653 | E27: =IFERROR((SUMIFS(Transacciones!$G$2:$G1001,Transacciones!$A$2:$A1001,A27,Transacciones!$C$2:$C1001,"Compra")-SUMIFS(Transacciones!$G$2:$G1001,Transacciones!$A$2:$A1001,A27,Transacciones!$C$2:$C1001,"Venta"))/C27,0) -> 1220.9615 | F27: 1118 | G27: =C27*E27 -> 31745 | H27: =F27*C27 -> 29068 | I27: =H27-G27 -> -2677 | J27: =IFERROR(I27/G27,0) -> -0.084328241 | K27: Eco
A28: NDT5D | B28: ON | C28: 98 | D28: =(H28/$F$2) -> 0.0085988312 | E28: =IFERROR((SUMIFS(Transacciones!$G$2:$G1001,Transacciones!$A$2:$A1001,A28,Transacciones!$C$2:$C1001,"Compra")-SUMIFS(Transacciones!$G$2:$G1001,Transacciones!$A$2:$A1001,A28,Transacciones!$C$2:$C1001,"Venta"))/C28,0) -> 1135 | F28: 900.3 | G28: =C28*E28 -> 111230 | H28: =F28*C28 -> 88229.4 | I28: =H28-G28 -> -23000.6 | J28: =IFERROR(I28/G28,0) -> -0.20678414 | K28: Ppi
A29: RUCDD | B29: ON | C29: =SUMIFS(Transacciones!$D$2:$D1001,Transacciones!$A$2:$A1001,A29,Transacciones!$C$2:$C1001,"Compra")-SUMIFS(Transacciones!$D$2:$D1001,Transacciones!$A$2:$A1001,A29,Transacciones!$C$2:$C1001,"Venta") -> 99 | D29: =(H29/$F$2) -> 0.01111511 | E29: =IFERROR((SUMIFS(Transacciones!$G$2:$G1001,Transacciones!$A$2:$A1001,A29,Transacciones!$C$2:$C1001,"Compra")-SUMIFS(Transacciones!$G$2:$G1001,Transacciones!$A$2:$A1001,A29,Transacciones!$C$2:$C1001,"Venta"))/C29,0) -> 1315.0625 | F29: 1152 | G29: =C29*E29 -> 130191.19 | H29: =F29*C29 -> 114048 | I29: =H29-G29 -> -16143.188 | J29: =IFERROR(I29/G29,0) -> -0.12399601 | K29: Ppi
A30: YMCJD | B30: ON | C30: =SUMIFS(Transacciones!$D$2:$D1001,Transacciones!$A$2:$A1001,A30,Transacciones!$C$2:$C1001,"Compra")-SUMIFS(Transacciones!$D$2:$D1001,Transacciones!$A$2:$A1001,A30,Transacciones!$C$2:$C1001,"Venta") -> 98 | D30: =(H30/$F$2) -> 0.010668549 | E30: =IFERROR((SUMIFS(Transacciones!$G$2:$G1001,Transacciones!$A$2:$A1001,A30,Transacciones!$C$2:$C1001,"Compra")-SUMIFS(Transacciones!$G$2:$G1001,Transacciones!$A$2:$A1001,A30,Transacciones!$C$2:$C1001,"Venta"))/C30,0) -> 1197.8 | F30: 1117 | G30: =C30*E30 -> 117384.4 | H30: =F30*C30 -> 109466 | I30: =H30-G30 -> -7918.4 | J30: =IFERROR(I30/G30,0) -> -0.067457005 | K30: Ppi
A31: Adcap Ahorro Pesos Clase A | B31: FCI | C31: =SUMIFS(Transacciones!$D$2:$D1001,Transacciones!$A$2:$A1001,A31,Transacciones!$C$2:$C1001,"Compra")-SUMIFS(Transacciones!$D$2:$D1001,Transacciones!$A$2:$A1001,A31,Transacciones!$C$2:$C1001,"Venta") -> 38715.043 | D31: =(H31/$F$2) -> 0.051224117 | E31: =IFERROR((SUMIFS(Transacciones!$G$2:$G1001,Transacciones!$A$2:$A1001,A31,Transacciones!$C$2:$C1001,"Compra")-SUMIFS(Transacciones!$G$2:$G1001,Transacciones!$A$2:$A1001,A31,Transacciones!$C$2:$C1001,"Venta"))/C31,0) -> 12.9 | F31: 13.5759 | G31: =C31*E31 -> 499424.06 | H31: =F31*C31 -> 525591.56 | I31: =H31-G31 -> 26167.498 | J31: =IFERROR(I31/G31,0) -> 0.052395349 | K31: Ppi
A32: Allaria Diversificado Clase A | B32: FCI | C32: =SUMIFS(Transacciones!$D$2:$D1001,Transacciones!$A$2:$A1001,A32,Transacciones!$C$2:$C1001,"Compra")-SUMIFS(Transacciones!$D$2:$D1001,Transacciones!$A$2:$A1001,A32,Transacciones!$C$2:$C1001,"Venta") -> 10501.993 | D32: =(H32/$F$2) -> 0.12218281 | E32: =IFERROR((SUMIFS(Transacciones!$G$2:$G1001,Transacciones!$A$2:$A1001,A32,Transacciones!$C$2:$C1001,"Compra")-SUMIFS(Transacciones!$G$2:$G1001,Transacciones!$A$2:$A1001,A32,Transacciones!$C$2:$C1001,"Venta"))/C32,0) -> 104.14 | F32: 119.3747 | G32: =C32*E32 -> 1093677.6 | H32: =F32*C32 -> 1253672.3 | I32: =H32-G32 -> 159994.71 | J32: =IFERROR(I32/G32,0) -> 0.14629057 | K32: Ppi
A33: Delta Recursos Naturales Clase A | B33: FCI | C33: =SUMIFS(Transacciones!$D$2:$D1001,Transacciones!$A$2:$A1001,A33,Transacciones!$C$2:$C1001,"Compra")-SUMIFS(Transacciones!$D$2:$D1001,Transacciones!$A$2:$A1001,A33,Transacciones!$C$2:$C1001,"Venta") -> 120.775 | D33: =(H33/$F$2) -> 0.011384561 | E33: =IFERROR((SUMIFS(Transacciones!$G$2:$G1001,Transacciones!$A$2:$A1001,A33,Transacciones!$C$2:$C1001,"Compra")-SUMIFS(Transacciones!$G$2:$G1001,Transacciones!$A$2:$A1001,A33,Transacciones!$C$2:$C1001,"Venta"))/C33,0) -> 1067 | F33: 967.193 | G33: =C33*E33 -> 128866.93 | H33: =F33*C33 -> 116812.73 | I33: =H33-G33 -> -12054.19 | J33: =IFERROR(I33/G33,0) -> -0.093539831 | K33: Ppi
A34: Max Ahorro Pesos Clase A | B34: FCI | C34: =SUMIFS(Transacciones!$D$2:$D1001,Transacciones!$A$2:$A1001,A34,Transacciones!$C$2:$C1001,"Compra")-SUMIFS(Transacciones!$D$2:$D1001,Transacciones!$A$2:$A1001,A34,Transacciones!$C$2:$C1001,"Venta") -> 93074.373 | D34: =(H34/$F$2) -> 0.051915273 | E34: =IFERROR((SUMIFS(Transacciones!$G$2:$G1001,Transacciones!$A$2:$A1001,A34,Transacciones!$C$2:$C1001,"Compra")-SUMIFS(Transacciones!$G$2:$G1001,Transacciones!$A$2:$A1001,A34,Transacciones!$C$2:$C1001,"Venta"))/C34,0) -> 5.34195 | F34: 5.7232 | G34: =C34*E34 -> 497198.65 | H34: =F34*C34 -> 532683.25 | I34: =H34-G34 -> 35484.605 | J34: =IFERROR(I34/G34,0) -> 0.071369069 | K34: Ppi
A35: Schroder Renta Plus Clase A | B35: FCI | C35: =SUMIFS(Transacciones!$D$2:$D1001,Transacciones!$A$2:$A1001,A35,Transacciones!$C$2:$C1001,"Compra")-SUMIFS(Transacciones!$D$2:$D1001,Transacciones!$A$2:$A1001,A35,Transacciones!$C$2:$C1001,"Venta") -> 13039.771 | D35: =(H35/$F$2) -> 0.10939331 | E35: =IFERROR((SUMIFS(Transacciones!$G$2:$G1001,Transacciones!$A$2:$A1001,A35,Transacciones!$C$2:$C1001,"Compra")-SUMIFS(Transacciones!$G$2:$G1001,Transacciones!$A$2:$A1001,A35,Transacciones!$C$2:$C1001,"Venta"))/C35,0) -> 80.363892 | F35: 86.0785 | G35: =C35*E35 -> 1047926.8 | H35: =F35*C35 -> 1122443.9 | I35: =H35-G35 -> 74517.185 | J35: =IFERROR(I35/G35,0) -> 0.071109155 | K35: Ppi
A36: Fima Ahorro Peso | B36: FCI | C36: =SUMIFS(Transacciones!$D$2:$D1001,Transacciones!$A$2:$A1001,A36,Transacciones!$C$2:$C1001,"Compra")-SUMIFS(Transacciones!$D$2:$D1001,Transacciones!$A$2:$A1001,A36,Transacciones!$C$2:$C1001,"Venta") -> 2374.82 | D36: =(H36/$F$2) -> 0.10411592 | E36: =IFERROR((SUMIFS(Transacciones!$G$2:$G1001,Transacciones!$A$2:$A1001,A36,Transacciones!$C$2:$C1001,"Compra")-SUMIFS(Transacciones!$G$2:$G1001,Transacciones!$A$2:$A1001,A36,Transacciones!$C$2:$C1001,"Venta"))/C36,0) -> 421.08574 | F36: 449.84236 | G36: =C36*E36 -> 1000002.8 | H36: =F36*C36 -> 1068294.6 | I36: =H36-G36 -> 68291.806 | J36: =IFERROR(I36/G36,0) -> 0.068291612 | K36: Galicia
A37: Fima Ahorro Plus | B37: FCI | C37: =SUMIFS(Transacciones!$D$2:$D1001,Transacciones!$A$2:$A1001,A37,Transacciones!$C$2:$C1001,"Compra")-SUMIFS(Transacciones!$D$2:$D1001,Transacciones!$A$2:$A1001,A37,Transacciones!$C$2:$C1001,"Venta") -> 9615.98 | D37: =(H37/$F$2) -> 0.10427054 | E37: =IFERROR((SUMIFS(Transacciones!$G$2:$G1001,Transacciones!$A$2:$A1001,A37,Transacciones!$C$2:$C1001,"Compra")-SUMIFS(Transacciones!$G$2:$G1001,Transacciones!$A$2:$A1001,A37,Transacciones!$C$2:$C1001,"Venta"))/C37,0) -> 103.99364 | F37: 111.26074 | G37: =C37*E37 -> 1000000.7 | H37: =F37*C37 -> 1069881.1 | I37: =H37-G37 -> 69880.346 | J37: =IFERROR(I37/G37,0) -> 0.069880294 | K37: Galicia
A38: Fima Premium | B38: FCI | C38: =SUMIFS(Transacciones!$D$2:$D1001,Transacciones!$A$2:$A1001,A38,Transacciones!$C$2:$C1001,"Compra")-SUMIFS(Transacciones!$D$2:$D1001,Transacciones!$A$2:$A1001,A38,Transacciones!$C$2:$C1001,"Venta") -> 15844.09 | D38: =(H38/$F$2) -> 0.097097027 | E38: =IFERROR((SUMIFS(Transacciones!$G$2:$G1001,Transacciones!$A$2:$A1001,A38,Transacciones!$C$2:$C1001,"Compra")-SUMIFS(Transacciones!$G$2:$G1001,Transacciones!$A$2:$A1001,A38,Transacciones!$C$2:$C1001,"Venta"))/C38,0) -> 60.203245 | F38: 62.88 | G38: =C38*E38 -> 953865.62 | H38: =F38*C38 -> 996276.38 | I38: =H38-G38 -> 42410.755 | J38: =IFERROR(I38/G38,0) -> 0.04446198 | K38: Galicia
A39: S30S5 | B39: Letras | C39: =SUMIFS(Transacciones!$D$2:$D1001,Transacciones!$A$2:$A1001,A39,Transacciones!$C$2:$C1001,"Compra")-SUMIFS(Transacciones!$D$2:$D1001,Transacciones!$A$2:$A1001,A39,Transacciones!$C$2:$C1001,"Venta") -> 697617 | D39: =(H39/$F$2) -> 0.1058049 | E39: =IFERROR((SUMIFS(Transacciones!$G$2:$G1001,Transacciones!$A$2:$A1001,A39,Transacciones!$C$2:$C1001,"Compra")-SUMIFS(Transacciones!$G$2:$G1001,Transacciones!$A$2:$A1001,A39,Transacciones!$C$2:$C1001,"Venta"))/C39,0) -> 1.51 | F39: 1.55619 | G39: =C39*E39 -> 1053401.7 | H39: =F39*C39 -> 1085624.6 | I39: =H39-G39 -> 32222.929 | J39: =IFERROR(I39/G39,0) -> 0.030589404 | K39: Ppi
A40: S12S5 | B40: Letras | C40: =SUMIFS(Transacciones!$D$2:$D1001,Transacciones!$A$2:$A1001,A40,Transacciones!$C$2:$C1001,"Compra")-SUMIFS(Transacciones!$D$2:$D1001,Transacciones!$A$2:$A1001,A40,Transacciones!$C$2:$C1001,"Venta") -> 40262 | D40: =(H40/$F$2) -> 0.0062221786 | E40: =IFERROR((SUMIFS(Transacciones!$G$2:$G1001,Transacciones!$A$2:$A1001,A40,Transacciones!$C$2:$C1001,"Compra")-SUMIFS(Transacciones!$G$2:$G1001,Transacciones!$A$2:$A1001,A40,Transacciones!$C$2:$C1001,"Venta"))/C40,0) -> 1.53 | F40: 1.5857 | G40: =C40*E40 -> 61600.86 | H40: =F40*C40 -> 63843.453 | I40: =H40-G40 -> 2242.5934 | J40: =IFERROR(I40/G40,0) -> 0.036405229 | K40: Ppi
...

Sheet Agosto
A1: Portfolio De Inversiones | C1: P&L | D1: P&L % | E1: Valor Medio Total | F1: Valor Portolio | G1: Efectivo | H1: Medio+Efectivo | I1: Portfolio+Efectivo | M1: Opc/Futuros | N1: =SUMIF(B4:B999,M1,G4:G999) -> 0
C2: 310357.07 | D2: 0.035332511 | E2: 8783895.1 | F2: 9094252.2 | G2: 300653.56 | H2: 9084548.7 | I2: 9394905.8 | M2: Acciones | N2: =SUMIF($B$5:B999,M2,$H$5:H999) -> 305751.82
M3: Bonos | N3: =SUMIF($B$5:B1000,M3,$H$5:H1000) -> 51180
A4: Ticker | B4: Tipo | C4: Cantidad | D4: % Portfolio | E4: Costo medio | F4: Precio Actual | G4: Valor Medio | H4: Valor de Mercado | I4: P&L | J4: P&L % | K4: Broker | M4: Cedear | N4: =SUMIF($B$5:B1001,M4,$H$5:H1001) -> 683313 | P4: P&L Julio/Junio
A5: ALUA | B5: Acciones | C5: 15 | D5: =(H5/$F$2) -> 0.0011603483 | E5: 984 | F5: 703.5 | G5: =C5*E5 -> 14760 | H5: =F5*C5 -> 10552.5 | I5: =H5-G5 -> -4207.5 | J5: =IFERROR(I5/G5,0) -> -0.28506098 | K5: Eco | M5: ON | N5: =SUMIF($B$5:B1002,M5,$H$5:H1002) -> 340811.4 | P5: =SUM(I5-Junio!I5) -> -187.5
A6: BYMA | B6: Acciones | C6: 30 | D6: =(H6/$F$2) -> 0.00053275408 | E6: 371.26667 | F6: 161.5 | G6: =C6*E6 -> 11138 | H6: =F6*C6 -> 4845 | I6: =H6-G6 -> -6293 | J6: =IFERROR(I6/G6,0) -> -0.56500269 | K6: Eco | M6: FCI | N6: =SUMIF($B$5:B1003,M6,$H$5:H1003) -> 6685655.9 | P6: =SUM(I6-Junio!I6) -> -915
A7: CEPU | B7: Acciones | C7: 20 | D7: =(H7/$F$2) -> 0.0027973713 | E7: 1740 | F7: 1272 | G7: =C7*E7 -> 34800 | H7: =F7*C7 -> 25440 | I7: =H7-G7 -> -9360 | J7: =IFERROR(I7/G7,0) -> -0.26896552 | K7: Eco | M7: Letras | N7: =SUMIF($B$5:B1004,M7,$H$5:H1004) -> 2344814 | P7: =SUM(I7-Junio!I7) -> -2960
A8: COME | B8: Acciones | C8: 46 | D8: =(H8/$F$2) -> 0.00017663025 | E8: 232.2337 | F8: 34.92 | G8: =C8*E8 -> 10682.75 | H8: =F8*C8 -> 1606.32 | I8: =H8-G8 -> -9076.43 | J8: =IFERROR(I8/G8,0) -> -0.84963422 | K8: Eco | M8: Cripto | N8: =SUMIF($B$5:B1005,M8,$H$5:H1005) -> 31430 | P8: =SUM(I8-Junio!I8) -> -3821.68
A9: EDN | B9: Acciones | C9: 25 | D9: =(H9/$F$2) -> 0.0043983825 | E9: 1270.6 | F9: 1600 | G9: =C9*E9 -> 31765 | H9: =F9*C9 -> 40000 | I9: =H9-G9 -> 8235 | J9: =IFERROR(I9/G9,0) -> 0.2592476 | K9: Eco | M9: Efectivo | N9: 107420 | P9: =SUM(I9-Junio!I9) -> 1875
A10: MORI | B10: Acciones | C10: 100 | D10: =(H10/$F$2) -> 0.00033317748 | E10: 394 | F10: 30.3 | G10: =C10*E10 -> 39400 | H10: =F10*C10 -> 3030 | I10: =H10-G10 -> -36370 | J10: =IFERROR(I10/G10,0) -> -0.92309645 | K10: Eco | M10: Total | N10: =SUM(N1:N9) -> 10550376
A11: PAMP | B11: Acciones | C11: 20 | D11: =(H11/$F$2) -> 0.0074387644 | E11: 4200 | F11: 3382.5 | G11: =C11*E11 -> 84000 | H11: =F11*C11 -> 67650 | I11: =H11-G11 -> -16350 | J11: =IFERROR(I11/G11,0) -> -0.19464286 | K11: Eco
A12: SEMI | B12: Acciones | C12: 7660 | D12: =(H12/$F$2) -> 0.015498141 | E12: 40 | F12: 18.4 | G12: =C12*E12 -> 306400 | H12: =F12*C12 -> 140944 | I12: =H12-G12 -> -165456 | J12: =IFERROR(I12/G12,0) -> -0.54 | K12: Eco | M12: Eco | N12: =SUMIF($K$5:$K999,M12,$H$5:$H999) -> 1069312.8
A13: TXAR | B13: Acciones | C13: 23 | D13: =(H13/$F$2) -> 0.0012847675 | E13: 963 | F13: 508 | G13: =C13*E13 -> 22149 | H13: =F13*C13 -> 11684 | I13: =H13-G13 -> -10465 | J13: =IFERROR(I13/G13,0) -> -0.47248183 | K13: Eco | M13: Ppi | N13: =SUMIF($K$5:$K1000,M13,$H$5:$H1000) -> 6207761.2
A14: AMZN | B14: Cedear | C14: 45 | D14: =(H14/$F$2) -> 0.011618327 | E14: 1895 | F14: 2348 | G14: =C14*E14 -> 85275 | H14: =F14*C14 -> 105660 | I14: =H14-G14 -> 20385 | J14: =IFERROR(I14/G14,0) -> 0.23905013 | K14: Eco | M14: Binance | N14: =SUMIF($K$5:$K1001,M14,$H$5:$H1001) -> 31430
A15: BABA | B15: Cedear | C15: 1 | D15: =(H15/$F$2) -> 0.0025818505 | E15: 11400 | F15: 23480 | G15: =C15*E15 -> 11400 | H15: =F15*C15 -> 23480 | I15: =H15-G15 -> 12080 | J15: =IFERROR(I15/G15,0) -> 1.0596491 | K15: Eco | M15: Galicia | N15: =SUMIF($K$5:$K1002,M15,$H$5:$H1002) -> 3134452.1
A16: CDE | B16: Cedear | C16: 5 | D16: =(H16/$F$2) -> 0.011320337 | E16: 7400 | F16: 20590 | G16: =C16*E16 -> 37000 | H16: =F16*C16 -> 102950 | I16: =H16-G16 -> 65950 | J16: =IFERROR(I16/G16,0) -> 1.7824324 | K16: Eco | M16: Efectivo | N16: 107420
A17: ETHA | B17: Cedear | C17: 5 | D17: =(H17/$F$2) -> 0.0051186177 | E17: 5970 | F17: 9310 | G17: =C17*E17 -> 29850 | H17: =F17*C17 -> 46550 | I17: =H17-G17 -> 16700 | J17: =IFERROR(I17/G17,0) -> 0.55946399 | K17: Eco | M17: Total | N17: =SUM(N12:N16) -> 10550376
A18: GOOGL | B18: Cedear | C18: 25 | D18: =(H18/$F$2) -> 0.016026606 | E18: 3995 | F18: 5830 | G18: =C18*E18 -> 99875 | H18: =F18*C18 -> 145750 | I18: =H18-G18 -> 45875 | J18: =IFERROR(I18/G18,0) -> 0.45932416 | K18: Eco
A19: IBM | B19: Cedear | C19: 1 | D19: =(H19/$F$2) -> 0.0027006069 | E19: 17850 | F19: 24560 | G19: =C19*E19 -> 17850 | H19: =F19*C19 -> 24560 | I19: =H19-G19 -> 6710 | J19: =IFERROR(I19/G19,0) -> 0.37591036 | K19: Eco
A20: KO | B20: Cedear | C20: 1 | D20: =(H20/$F$2) -> 0.0021420123 | E20: 15000 | F20: 19480 | G20: =C20*E20 -> 15000 | H20: =F20*C20 -> 19480 | I20: =H20-G20 -> 4480 | J20: =IFERROR(I20/G20,0) -> 0.29866667 | K20: Eco
A21: LAC | B21: Cedear | C21: 9 | D21: =(H21/$F$2) -> 0.0040248499 | E21: 3655 | F21: 4067 | G21: =C21*E21 -> 32895 | H21: =F21*C21 -> 36603 | I21: =H21-G21 -> 3708 | J21: =IFERROR(I21/G21,0) -> 0.1127223 | K21: Eco
A22: MSFT | B22: Cedear | C22: 1 | D22: =(H22/$F$2) -> 0.0026412287 | E22: 17775 | F22: 24020 | G22: =C22*E22 -> 17775 | H22: =F22*C22 -> 24020 | I22: =H22-G22 -> 6245 | J22: =IFERROR(I22/G22,0) -> 0.35133615 | K22: Eco
A23: PFE | B23: Cedear | C23: 1 | D23: =(H23/$F$2) -> 0.00097314213 | E23: 7790 | F23: 8850 | G23: =C23*E23 -> 7790 | H23: =F23*C23 -> 8850 | I23: =H23-G23 -> 1060 | J23: =IFERROR(I23/G23,0) -> 0.13607189 | K23: Eco
A24: SPY | B24: Cedear | C24: 2 | D24: =(H24/$F$2) -> 0.01025263 | E24: 35825 | F24: 46620 | G24: =C24*E24 -> 71650 | H24: =F24*C24 -> 93240 | I24: =H24-G24 -> 21590 | J24: =IFERROR(I24/G24,0) -> 0.30132589 | K24: Eco
A25: VIST | B25: Cedear | C25: 3 | D25: =(H25/$F$2) -> 0.0057365904 | E25: 21041.667 | F25: 17390 | G25: =C25*E25 -> 63125 | H25: =F25*C25 -> 52170 | I25: =H25-G25 -> -10955 | J25: =IFERROR(I25/G25,0) -> -0.17354455 | K25: Eco
A26: AE38 | B26: Bonos | C26: 60 | D26: =(H26/$F$2) -> 0.0056277304 | E26: 740 | F26: 853 | G26: =C26*E26 -> 44400 | H26: =F26*C26 -> 51180 | I26: =H26-G26 -> 6780 | J26: =IFERROR(I26/G26,0) -> 0.1527027 | K26: Eco
A27: YMCJO | B27: ON | C27: 26 | D27: =(H27/$F$2) -> 0.0031963046 | E27: 1220.9615 | F27: 1118 | G27: =C27*E27 -> 31745 | H27: =F27*C27 -> 29068 | I27: =H27-G27 -> -2677 | J27: =IFERROR(I27/G27,0) -> -0.084328241 | K27: Eco
A28: NDT5D | B28: ON | C28: 98 | D28: =(H28/$F$2) -> 0.0097016663 | E28: 1135 | F28: 900.3 | G28: =C28*E28 -> 111230 | H28: =F28*C28 -> 88229.4 | I28: =H28-G28 -> -23000.6 | J28: =IFERROR(I28/G28,0) -> -0.20678414 | K28: Ppi
A29: RUCDD | B29: ON | C29: 99 | D29: =(H29/$F$2) -> 0.012540668 | E29: 1315.0625 | F29: 1152 | G29: =C29*E29 -> 130191.19 | H29: =F29*C29 -> 114048 | I29: =H29-G29 -> -16143.188 | J29: =IFERROR(I29/G29,0) -> -0.12399601 | K29: Ppi
... A41: BTC | B41: Cripto | C41: 1 | D41: =(H41/$F$2) -> 0.0034560291 | E41: 22000 | F41: 31430 | G41: =C41*E41 -> 22000 | H41: =F41*C41 -> 31430 | I41: =H41-G41 -> 9430 | J41: =IFERROR(I41/G41,0) -> 0.42863636 | K41: Binance

Sheet Julio
A1: Portfolio De Inversiones | C1: P&L | D1: P&L % | E1: Valor Medio Total | F1: Valor Portolio | G1: Efectivo | H1: Medio+Efectivo | I1: Portfolio+Efectivo | M1: Opc/Futuros | N1: 0
C2: 853839.32 | D2: 0.078298801 | E2: 10904884 | F2: 11758723 | G2: 217000 | H2: 11121884 | I2: 11975723 | M2: Acciones | N2: 414838
M3: Bonos | N3: 54780
A4: Ticker | B4: Tipo | C4: Cantidad | D4: % Portfolio | E4: Costo medio | F4: Precio Actual | G4: Valor Medio | H4: Valor de Mercado | I4: P&L | J4: P&L % | K4: Broker | M4: Cedear | N4: 574225 | P4: P&L Junio/Mayo
A5: ALUA | B5: Acciones | C5: 15 | D5: 0.00095546089 | E5: 984 | F5: 749 | G5: 14760 | H5: 11235 | I5: -3525 | J5: -0.23882114 | K5: Eco | M5: ON | N5: 396699 | P5: -120
A6: BYMA | B6: Acciones | C6: 30 | D6: 0.00051536208 | E6: 371.26667 | F6: 202 | G6: 11138 | H6: 6060 | I6: -5078 | J6: -0.45591668 | K6: Eco | M6: FCI | N6: 6911392.9 | P6: -270
A7: CEPU | B7: Acciones | C7: 20 | D7: 0.0027979229 | E7: 1740 | F7: 1645 | G7: 34800 | H7: 32900 | I7: -1900 | J7: -0.054597701 | K7: Eco | M7: Letras | N7: 3375673.7 | P7: 2900
A8: COME | B8: Acciones | C8: 46 | D8: 0.00049682265 | E8: 232.2337 | F8: 127 | G8: 10682.75 | H8: 5842 | I8: -4840.75 | J8: -0.45313707 | K8: Eco | M8: Cripto | N8: 31114.52 | P8: -782
A9: EDN | B9: Acciones | C9: 25 | D9: 0.0042096408 | E9: 1270.6 | F9: 1980 | G9: 31765 | H9: 49500 | I9: 17735 | J9: 0.5583189 | K9: Eco | M9: Efectivo | N9: 107420 | P9: 9500
A10: MORI | B10: Acciones | C10: 100 | D10: 0.0018794558 | E10: 394 | F10: 221 | G10: 39400 | H10: 22100 | I10: -17300 | J10: -0.43908629 | K10: Eco | M10: Total | N10: 11866143
A11: PAMP | B11: Acciones | C11: 20 | D11: 0.006965042 | E11: 4200 | F11: 4095 | G11: 84000 | H11: 81900 | I11: -2100 | J11: -0.025 | K11: Eco
A12: SEMI | B12: Acciones | C12: 7660 | D12: 0.016188067 | E12: 40 | F12: 24.85 | G12: 306400 | H12: 190351 | I12: -116049 | J12: -0.37875 | K12: Eco | M12: Eco | N12: 1081875
A13: TXAR | B13: Acciones | C13: 23 | D13: 0.0012713966 | E13: 963 | F13: 650 | G13: 22149 | H13: 14950 | I13: -7199 | J13: -0.32502596 | K13: Eco | M13: Ppi | N13: 7379592.5
A14: AMZN | B14: Cedear | C14: 45 | D14: 0.0077112965 | E14: 1895 | F14: 2015 | G14: 85275 | H14: 90675 | I14: 5400 | J14: 0.063324538 | K14: Eco | M14: Binance | N14: 31114.52
A15: BABA | B15: Cedear | C15: 1 | D15: 0.0015095176 | E15: 11400 | F15: 17750 | G15: 11400 | H15: 17750 | I15: 6350 | J15: 0.55701754 | K15: Eco | M15: Galicia | N15: 3266141
A16: CDE | B16: Cedear | C16: 5 | D16: 0.005262051 | E16: 7400 | F16: 12375 | G16: 37000 | H16: 61875 | I16: 24875 | J16: 0.6722973 | K16: Eco | M16: Efectivo | N16: 107420
A17: ETHA | B17: Cedear | C17: 5 | D17: 0.0032273913 | E17: 5970 | F17: 7590 | G17: 29850 | H17: 37950 | I17: 8100 | J17: 0.27135678 | K17: Eco | M17: Total | N17: 11866143
A18: GOOGL | B18: Cedear | C18: 25 | D18: 0.0096842998 | E18: 3995 | F18: 4555 | G18: 99875 | H18: 113875 | I18: 14000 | J18: 0.14017522 | K18: Eco
A19: IBM | B19: Cedear | C19: 1 | D19: 0.0019411121 | E19: 17850 | F19: 22825 | G19: 17850 | H19: 22825 | I19: 4975 | J19: 0.27871148 | K19: Eco
A20: KO | B20: Cedear | C20: 1 | D20: 0.0015924348 | E20: 15000 | F20: 18725 | G20: 15000 | H20: 18725 | I20: 3725 | J20: 0.24833333 | K20: Eco
A21: LAC | B21: Cedear | C21: 9 | D21: 0.002770709 | E21: 3655 | F21: 3620 | G21: 32895 | H21: 32580 | I21: -315 | J21: -0.0095759234 | K21: Eco
A22: MSFT | B22: Cedear | C22: 1 | D22: 0.0020729292 | E22: 17775 | F22: 24375 | G22: 17775 | H22: 24375 | I22: 6600 | J22: 0.37130802 | K22: Eco
A23: PFE | B23: Cedear | C23: 1 | D23: 0.00068204685 | E23: 7790 | F23: 8020 | G23: 7790 | H23: 8020 | I23: 230 | J23: 0.029525032 | K23: Eco
A24: SPY | B24: Cedear | C24: 2 | D24: 0.0072967107 | E24: 35825 | F24: 42900 | G24: 71650 | H24: 85800 | I24: 14150 | J24: 0.19748779 | K24: Eco
A25: VIST | B25: Cedear | C25: 3 | D25: 0.0050834601 | E25: 21041.667 | F25: 19925 | G25: 63125 | H25: 59775 | I25: -3350 | J25: -0.053069307 | K25: Eco
A26: AE38 | B26: Bonos | C26: 60 | D26: 0.0046586691 | E26: 740 | F26: 913 | G26: 44400 | H26: 54780 | I26: 10380 | J26: 0.23378378 | K26: Eco
A27: MR39O | B27: ON | C27: 12 | D27: 0.00076232767 | E27: 1169 | F27: 747 | G27: 14028 | H27: 8964 | I27: -5064 | J27: -0.3609923 | K27: Eco
A28: YMCJO | B28: ON | C28: 26 | D28: 0.0024720371 | E28: 1220.9615 | F28: 1118 | G28: 31745 | H28: 29068 | I28: -2677 | J28: -0.084328241 | K28: Eco
A29: NDT5D | B29: ON | C29: 98 | D29: 0.0086676078 | E29: 1135 | F29: 1040 | G29: 111230 | H29: 101920 | I29: -9310 | J29: -0.083700441 | K29: Ppi
... A42: BTC | B42: Cripto | C42: 1 | D42: 0.0026460798 | E42: 22000 | F42: 31114.52 | G42: 22000 | H42: 31114.52 | I42: 9114.52 | J42: 0.41429636 | K42: Binance

Sheet Junio
A1: Portfolio De Inversiones | C1: P&L | D1: P&L % | E1: Valor Medio Total | F1: Valor Portolio | G1: Efectivo | H1: Medio+Efectivo | I1: Portfolio+Efectivo | M1: Opc/Futuros | N1: 0
C2: 384956.31 | D2: 0.035301276 | E2: 10904884 | F2: 11289840 | G2: 217000 | H2: 11121884 | I2: 11506840 | M2: Acciones | N2: 365441
M3: Bonos | N3: 52740
A4: Ticker | B4: Tipo | C4: Cantidad | D4: % Portfolio | E4: Costo medio | F4: Precio Actual | G4: Valor Medio | H4: Valor de Mercado | I4: P&L | J4: P&L % | K4: Broker | M4: Cedear | N4: 505953 | P4: P&L Junio/Mayo
A5: ALUA | B5: Acciones | C5: 15 | D5: 0.0009512978 | E5: 984 | F5: 716 | G5: 14760 | H5: 10740 | I5: -4020 | J5: -0.27235772 | K5: Eco | M5: ON | N5: 353492 | P5: -615
A6: BYMA | B6: Acciones | C6: 30 | D6: 0.00051019323 | E6: 371.26667 | F6: 192 | G6: 11138 | H6: 5760 | I6: -5378 | J6: -0.4828515 | K6: Eco | M6: FCI | N6: 6724481.9 | P6: -570
A7: CEPU | B7: Acciones | C7: 20 | D7: 0.0025155361 | E7: 1740 | F7: 1420 | G7: 34800 | H7: 28400 | I7: -6400 | J7: -0.18390805 | K7: Eco | M7: Letras | N7: 3259732.2 | P7: -1600
A8: COME | B8: Acciones | C8: 46 | D8: 0.00048078626 | E8: 232.2337 | F8: 118 | G8: 10682.75 | H8: 5428 | I8: -5254.75 | J8: -0.49189113 | K8: Eco | M8: Cripto | N8: 28000 | P8: -1196
A9: EDN | B9: Acciones | C9: 25 | D9: 0.00337693 | E9: 1270.6 | F9: 1525 | G9: 31765 | H9: 38125 | I9: 6360 | J9: 0.20022037 | K9: Eco | M9: Efectivo | N9: 107420 | P9: -1875
A10: MORI | B10: Acciones | C10: 100 | D10: 0.0018246494 | E10: 394 | F10: 206 | G10: 39400 | H10: 20600 | I10: -18800 | J10: -0.47715736 | K10: Eco | M10: Total | N10: 11397260
A11: PAMP | B11: Acciones | C11: 20 | D11: 0.0065279933 | E11: 4200 | F11: 3685 | G11: 84000 | H11: 73700 | I11: -10300 | J11: -0.12261905 | K11: Eco
A12: SEMI | B12: Acciones | C12: 7660 | D12: 0.014926695 | E12: 40 | F12: 22 | G12: 306400 | H12: 168520 | I12: -137880 | J12: -0.45 | K12: Eco | M12: Eco | N12: 963854
A13: TXAR | B13: Acciones | C13: 23 | D13: 0.0012549336 | E13: 963 | F13: 616 | G13: 22149 | H13: 14168 | I13: -7981 | J13: -0.36033229 | K13: Eco | M13: Ppi | N13: 7082321.5
A14: AMZN | B14: Cedear | C14: 45 | D14: 0.0075731808 | E14: 1895 | F14: 1900 | G14: 85275 | H14: 85500 | I14: 225 | J14: 0.0026385224 | K14: Eco | M14: Binance | N14: 28000
A15: BABA | B15: Cedear | C15: 1 | D15: 0.0013884165 | E15: 11400 | F15: 15675 | G15: 11400 | H15: 15675 | I15: 4275 | J15: 0.375 | K15: Eco | M15: Galicia | N15: 3215664.5
A16: CDE | B16: Cedear | C16: 5 | D16: 0.0048968807 | E16: 7400 | F16: 11057 | G16: 37000 | H16: 55285 | I16: 18285 | J16: 0.49418919 | K16: Eco | M16: Efectivo | N16: 107420
A17: ETHA | B17: Cedear | C17: 5 | D17: 0.0021501633 | E17: 5970 | F17: 4855 | G17: 29850 | H17: 24275 | I17: -5575 | J17: -0.18676717 | K17: Eco | M17: Total | N17: 11397260
A18: GOOGL | B18: Cedear | C18: 25 | D18: 0.0081932073 | E18: 3995 | F18: 3700 | G18: 99875 | H18: 92500 | I18: -7375 | J18: -0.073842303 | K18: Eco
A19: IBM | B19: Cedear | C19: 1 | D19: 0.0021080901 | E19: 17850 | F19: 23800 | G19: 17850 | H19: 23800 | I19: 5950 | J19: 0.33333333 | K19: Eco
A20: KO | B20: Cedear | C20: 1 | D20: 0.0015722101 | E20: 15000 | F20: 17750 | G20: 15000 | H20: 17750 | I20: 2750 | J20: 0.18333333 | K20: Eco
A21: LAC | B21: Cedear | C21: 9 | D21: 0.0025979996 | E21: 3655 | F21: 3259 | G21: 32895 | H21: 29331 | I21: -3564 | J21: -0.10834473 | K21: Eco
A22: MSFT | B22: Cedear | C22: 1 | D22: 0.0017944453 | E22: 17775 | F22: 20259 | G22: 17775 | H22: 20259 | I22: 2484 | J22: 0.13974684 | K22: Eco
A23: PFE | B23: Cedear | C23: 1 | D23: 0.00068202915 | E23: 7790 | F23: 7700 | G23: 7790 | H23: 7700 | I23: -90 | J23: -0.011553273 | K23: Eco
A24: SPY | B24: Cedear | C24: 2 | D24: 0.0066962862 | E24: 35825 | F24: 37800 | G24: 71650 | H24: 75600 | I24: 3950 | J24: 0.0551291 | K24: Eco
A25: VIST | B25: Cedear | C25: 3 | D25: 0.0051619863 | E25: 21041.667 | F25: 19426 | G25: 63125 | H25: 58278 | I25: -4847 | J25: -0.076784158 | K25: Eco
A26: AE38 | B26: Bonos | C26: 60 | D26: 0.0046714568 | E26: 740 | F26: 879 | G26: 44400 | H26: 52740 | I26: 8340 | J26: 0.18783784 | K26: Eco
A27: MR39O | B27: ON | C27: 12 | D27: 0.00075466082 | E27: 1169 | F27: 710 | G27: 14028 | H27: 8520 | I27: -5508 | J27: -0.39264328 | K27: Eco
A28: YMCJO | B28: ON | C28: 26 | D28: 0.0027635467 | E28: 1220.9615 | F28: 1200 | G28: 31745 | H28: 31200 | I28: -545 | J28: -0.017168058 | K28: Eco
A29: NDT5D | B29: ON | C29: 98 | D29: 0.0079946217 | E29: 1135 | F29: 921 | G29: 111230 | H29: 90258 | I29: -20972 | J29: -0.18854626 | K29: Ppi
... A42: BTC | B42: Cripto | C42: 1 | D42: 0.002480106 | E42: 22000 | F42: 28000 | G42: 22000 | H42: 28000 | I42: 6000 | J42: 0.27272727 | K42: Binance

Sheet Mayo
A1: Portfolio De Inversiones | C1: P&L | D1: P&L % | E1: Valor Medio Total | F1: Valor Portolio | G1: Efectivo | H1: Medio+Efectivo | I1: Portfolio+Efectivo | M1: Opc/Futuros | N1: 0
C2: 439491.15 | D2: 0.04517191 | E2: 9729302 | F2: 10168793 | G2: 139000 | H2: 9868302 | I2: 10307793 | M2: Acciones | N2: 397929
M3: Bonos | N3: 51180
A4: Ticker | B4: Tipo | C4: Cantidad | D4: % Portfolio | E4: Costo medio | F4: Precio Actual | G4: Valor Medio | H4: Valor de Mercado | I4: P&L | J4: P&L % | K4: Broker | M4: Cedear | N4: 461810
A5: ALUA | B5: Acciones | C5: 15 | D5: 0.0011166517 | E5: 984 | F5: 757 | G5: 14760 | H5: 11355 | I5: -3405 | J5: -0.23069106 | K5: Eco | M5: ON | N5: 341521.4
A6: BYMA | B6: Acciones | C6: 30 | D6: 0.00062249275 | E6: 371.26667 | F6: 211 | G6: 11138 | H6: 6330 | I6: -4808 | J6: -0.43167535 | K6: Eco | M6: FCI | N6: 6685655.9
A7: CEPU | B7: Acciones | C7: 20 | D7: 0.0029502026 | E7: 1740 | F7: 1500 | G7: 34800 | H7: 30000 | I7: -4800 | J7: -0.13793103 | K7: Eco | M7: Letras | N7: 2205766.2
A8: COME | B8: Acciones | C8: 46 | D8: 0.00065140474 | E8: 232.2337 | F8: 144 | G8: 10682.75 | H8: 6624 | I8: -4058.75 | J8: -0.37993494 | K8: Eco | M8: Cripto | N8: 24930.7
A9: EDN | B9: Acciones | C9: 25 | D9: 0.0039336035 | E9: 1270.6 | F9: 1600 | G9: 31765 | H9: 40000 | I9: 8235 | J9: 0.2592476 | K9: Eco | M9: Efectivo | N9: 29244.57
A10: MORI | B10: Acciones | C10: 100 | D10: 0.0025175062 | E10: 394 | F10: 256 | G10: 39400 | H10: 25600 | I10: -13800 | J10: -0.35025381 | K10: Eco | M10: Total | N10: 10198038
A11: PAMP | B11: Acciones | C11: 20 | D11: 0.0070509842 | E11: 4200 | F11: 3585 | G11: 84000 | H11: 71700 | I11: -12300 | J11: -0.14642857 | K11: Eco
A12: SEMI | B12: Acciones | C12: 7660 | D12: 0.018794462 | E12: 40 | F12: 24.95 | G12: 306400 | H12: 191117 | I12: -115283 | J12: -0.37625 | K12: Eco | M12: Eco | N12: 940697
A13: TXAR | B13: Acciones | C13: 23 | D13: 0.0014950643 | E13: 963 | F13: 661 | G13: 22149 | H13: 15203 | I13: -6946 | J13: -0.31360332 | K13: Eco | M13: Ppi | N13: 6068713.3
A14: AMZN | B14: Cedear | C14: 45 | D14: 0.0076115227 | E14: 1895 | F14: 1720 | G14: 85275 | H14: 77400 | I14: -7875 | J14: -0.092348285 | K14: Eco | M14: Binance | N14: 24930.7
A15: BABA | B15: Cedear | C15: 1 | D15: 0.0014996863 | E15: 11400 | F15: 15250 | G15: 11400 | H15: 15250 | I15: 3850 | J15: 0.3377193 | K15: Eco | M15: Galicia | N15: 3134452.1
A16: CDE | B16: Cedear | C16: 5 | D16: 0.0036336662 | E16: 7400 | F16: 7390 | G16: 37000 | H16: 36950 | I16: -50 | J16: -0.0013513514 | K16: Eco | M16: Efectivo | N16: 107420
A17: ETHA | B17: Cedear | C17: 5 | D17: 0.002261822 | E17: 5970 | F17: 4600 | G17: 29850 | H17: 23000 | I17: -6850 | J17: -0.22948074 | K17: Eco | M17: Total | N17: 10276213
A18: GOOGL | B18: Cedear | C18: 25 | D18: 0.0085801726 | E18: 3995 | F18: 3490 | G18: 99875 | H18: 87250 | I18: -12625 | J18: -0.12640801 | K18: Eco
A19: IBM | B19: Cedear | C19: 1 | D19: 0.0020602248 | E19: 17850 | F19: 20950 | G19: 17850 | H19: 20950 | I19: 3100 | J19: 0.17366947 | K19: Eco | M19: P&L Mayo/Abril
A20: KO | B20: Cedear | C20: 1 | D20: 0.001693908 | E20: 15000 | F20: 17225 | G20: 15000 | H20: 17225 | I20: 2225 | J20: 0.14833333 | K20: Eco | M20: Opc/Futuros | N20: 0
A21: LAC | B21: Cedear | C21: 9 | D21: 0.002810068 | E21: 3655 | F21: 3175 | G21: 32895 | H21: 28575 | I21: -4320 | J21: -0.13132695 | K21: Eco | M21: Acciones | N21: -40985
A22: MSFT | B22: Cedear | C22: 1 | D22: 0.0018094576 | E22: 17775 | F22: 18400 | G22: 17775 | H22: 18400 | I22: 625 | J22: 0.035161744 | K22: Eco | M22: Bonos | N22: -118520
A23: PFE | B23: Cedear | C23: 1 | D23: 0.00068936401 | E23: 7790 | F23: 7010 | G23: 7790 | H23: 7010 | I23: -780 | J23: -0.10012837 | K23: Eco | M23: Cedear | N23: 3155
A24: SPY | B24: Cedear | C24: 2 | D24: 0.0069673952 | E24: 35825 | F24: 35425 | G24: 71650 | H24: 70850 | I24: -800 | J24: -0.011165387 | K24: Eco | M24: ON | N24: 8641.4
